Workbook

Sheet Traveller Types
A1: Traveller | B1: Characteristics
A2: Solo | B2: Freedom, self-discovery, flexibility
A3: Couple | B3: Romance, reconnection, privacy
A4: Family | B4: Shared memories, safety
A5: Friends | B5: Energy, activities
A6: Business | B6: Comfort, connectivity

Sheet Emotional Goals
A1: Emotional Goal
A2: Healing
A3: Celebration
A4: Freedom
A5: Escape
A6: Adventure
A7: Discovery
A8: Reconnection
A9: Slow Living
A10: Relax
A11: Explore
A12: Romance

Sheet Desired Experiences
A1: Desired Experience
A2: Beach
A3: Mountains
A4: Wildlife
A5: Culture
A6: Food
A7: Wellness
A8: Luxury
A9: Shopping
A10: Spiritual
A11: Adventure
A12: Photography
... A16: Celebrations

Sheet Destination Catalogue
A1: Destination | B1: Region
A2: Agra | B2: Agra
A3: Amritsar | B3: Golden Temple
A4: Amritsar | B4: Wagah Border
A5: Amritsar | B5: Jallianwala Bagh
A6: Andaman | B6: Port Blair
A7: Andaman | B7: Havelock
A8: Andaman | B8: Neil Island
A9: Andaman | B9: Baratang Island
A10: Andaman | B10: Ross Island
A11: Andaman | B11: North Bay Island
A12: Goa | B12: North Goa
... A108: Vietnam | B108: Da Nang

Sheet Compatibility Matrix
A1: Compatibility Matrix — Review View
A2: Score | B2: 5 | C2: 4 | D2: 3 | E2: 2 | F2: 1 | G2: 0 | H2: Every score reason is stored in Destination Intelligence.
A3: Meaning | B3: Exceptional Match | C3: Strong Match | D3: Suitable | E3: Limited Match | F3: Weak Match | G3: Contradiction | H3: Colour is supplementary; numeric score and reason code remain authoritative.
A4: Contradictions | B4: A 0 score is a deterministic rejection for that dimension.
A5: Confidence | B5: Operational confidence is qualitative and requires live review.
A7: Destination ID | B7: Region ID | C7: Destination | D7: Region | E7: Record Type | F7: Journey Base Status | G7: Traveller — Solo | H7: Traveller — Couple | I7: Traveller — Family | J7: Traveller — Friends | K7: Traveller — Business | L7: Emotion — Healing | M7: Emotion — Celebration | N7: Emotion — Freedom | O7: Emotion — Escape | P7: Emotion — Adventure | Q7: Emotion — Discovery | R7: Emotion — Reconnection | S7: Emotion — Slow Living | T7: Emotion — Relax | U7: Emotion — Explore | V7: Emotion — Romance | W7: Experience — Beach | X7: Experience — Mountains | Y7: Experience — Wildlife | Z7: Experience — Culture | AA7: Experience — Food | AB7: Experience — Wellness | AC7: Experience — Luxury | AD7: Experience — Shopping | AE7: Experience — Spiritual | AF7: Experience — Adventure | AG7: Experience — Photography | AH7: Experience — Island Hopping | AI7: Experience — Heritage | AJ7: Experience — Nature | AK7: Experience — Celebrations | AL7: Primary Contradiction Flags | AM7: Operational Confidence | AN7: Reason Reference
A8: ='Destination Intelligence'!B2 | B8: ='Destination Intelligence'!C2 | C8: ='Destination Intelligence'!D2 | D8: ='Destination Intelligence'!E2 | E8: ='Destination Intelligence'!G2 | F8: ='Destination Intelligence'!H2 | G8: ='Destination Intelligence'!BI2 | H8: ='Destination Intelligence'!BK2 | I8: ='Destination Intelligence'!BM2 | J8: ='Destination Intelligence'!BO2 | K8: ='Destination Intelligence'!BQ2 | L8: ='Destination Intelligence'!BS2 | M8: ='Destination Intelligence'!BU2 | N8: ='Destination Intelligence'!BW2 | O8: ='Destination Intelligence'!BY2 | P8: ='Destination Intelligence'!CA2 | Q8: ='Destination Intelligence'!CC2 | R8: ='Destination Intelligence'!CE2 | S8: ='Destination Intelligence'!CG2 | T8: ='Destination Intelligence'!CI2 | U8: ='Destination Intelligence'!CK2 | V8: ='Destination Intelligence'!CM2 | W8: ='Destination Intelligence'!CO2 | X8: ='Destination Intelligence'!CQ2 | Y8: ='Destination Intelligence'!CS2 | Z8: ='Destination Intelligence'!CU2 | AA8: ='Destination Intelligence'!CW2 | AB8: ='Destination Intelligence'!CY2 | AC8: ='Destination Intelligence'!DA2 | AD8: ='Destination Intelligence'!DC2 | AE8: ='Destination Intelligence'!DE2 | AF8: ='Destination Intelligence'!DG2 | AG8: ='Destination Intelligence'!DI2 | AH8: ='Destination Intelligence'!DK2 | AI8: ='Destination Intelligence'!DM2 | AJ8: ='Destination Intelligence'!DO2 | AK8: ='Destination Intelligence'!DQ2 | AL8: Wildlife, Island Hopping | AM8: Medium | AN8: india-agra-agra
A9: ='Destination Intelligence'!B3 | B9: ='Destination Intelligence'!C3 | C9: ='Destination Intelligence'!D3 | D9: ='Destination Intelligence'!E3 | E9: ='Destination Intelligence'!G3 | F9: ='Destination Intelligence'!H3 | G9: ='Destination Intelligence'!BI3 | H9: ='Destination Intelligence'!BK3 | I9: ='Destination Intelligence'!BM3 | J9: ='Destination Intelligence'!BO3 | K9: ='Destination Intelligence'!BQ3 | L9: ='Destination Intelligence'!BS3 | M9: ='Destination Intelligence'!BU3 | N9: ='Destination Intelligence'!BW3 | O9: ='Destination Intelligence'!BY3 | P9: ='Destination Intelligence'!CA3 | Q9: ='Destination Intelligence'!CC3 | R9: ='Destination Intelligence'!CE3 | S9: ='Destination Intelligence'!CG3 | T9: ='Destination Intelligence'!CI3 | U9: ='Destination Intelligence'!CK3 | V9: ='Destination Intelligence'!CM3 | W9: ='Destination Intelligence'!CO3 | X9: ='Destination Intelligence'!CQ3 | Y9: ='Destination Intelligence'!CS3 | Z9: ='Destination Intelligence'!CU3 | AA9: ='Destination Intelligence'!CW3 | AB9: ='Destination Intelligence'!CY3 | AC9: ='Destination Intelligence'!DA3 | AD9: ='Destination Intelligence'!DC3 | AE9: ='Destination Intelligence'!DE3 | AF9: ='Destination Intelligence'!DG3 | AG9: ='Destination Intelligence'!DI3 | AH9: ='Destination Intelligence'!DK3 | AI9: ='Destination Intelligence'!DM3 | AJ9: ='Destination Intelligence'!DO3 | AK9: ='Destination Intelligence'!DQ3 | AL9: Wildlife, Island Hopping, Celebrations | AM9: Medium | AN9: india-amritsar-golden-temple
A10: ='Destination Intelligence'!B4 | B10: ='Destination Intelligence'!C4 | C10: ='Destination Intelligence'!D4 | D10: ='Destination Intelligence'!E4 | E10: ='Destination Intelligence'!G4 | F10: ='Destination Intelligence'!H4 | G10: ='Destination Intelligence'!BI4 | H10: ='Destination Intelligence'!BK4 | I10: ='Destination Intelligence'!BM4 | J10: ='Destination Intelligence'!BO4 | K10: ='Destination Intelligence'!BQ4 | L10: ='Destination Intelligence'!BS4 | M10: ='Destination Intelligence'!BU4 | N10: ='Destination Intelligence'!BW4 | O10: ='Destination Intelligence'!BY4 | P10: ='Destination Intelligence'!CA4 | Q10: ='Destination Intelligence'!CC4 | R10: ='Destination Intelligence'!CE4 | S10: ='Destination Intelligence'!CG4 | T10: ='Destination Intelligence'!CI4 | U10: ='Destination Intelligence'!CK4 | V10: ='Destination Intelligence'!CM4 | W10: ='Destination Intelligence'!CO4 | X10: ='Destination Intelligence'!CQ4 | Y10: ='Destination Intelligence'!CS4 | Z10: ='Destination Intelligence'!CU4 | AA10: ='Destination Intelligence'!CW4 | AB10: ='Destination Intelligence'!CY4 | AC10: ='Destination Intelligence'!DA4 | AD10: ='Destination Intelligence'!DC4 | AE10: ='Destination Intelligence'!DE4 | AF10: ='Destination Intelligence'!DG4 | AG10: ='Destination Intelligence'!DI4 | AH10: ='Destination Intelligence'!DK4 | AI10: ='Destination Intelligence'!DM4 | AJ10: ='Destination Intelligence'!DO4 | AK10: ='Destination Intelligence'!DQ4 | AL10: Wildlife, Spiritual | AM10: Medium | AN10: india-amritsar-wagah-border
A11: ='Destination Intelligence'!B5 | B11: ='Destination Intelligence'!C5 | C11: ='Destination Intelligence'!D5 | D11: ='Destination Intelligence'!E5 | E11: ='Destination Intelligence'!G5 | F11: ='Destination Intelligence'!H5 | G11: ='Destination Intelligence'!BI5 | H11: ='Destination Intelligence'!BK5 | I11: ='Destination Intelligence'!BM5 | J11: ='Destination Intelligence'!BO5 | K11: ='Destination Intelligence'!BQ5 | L11: ='Destination Intelligence'!BS5 | M11: ='Destination Intelligence'!BU5 | N11: ='Destination Intelligence'!BW5 | O11: ='Destination Intelligence'!BY5 | P11: ='Destination Intelligence'!CA5 | Q11: ='Destination Intelligence'!CC5 | R11: ='Destination Intelligence'!CE5 | S11: ='Destination Intelligence'!CG5 | T11: ='Destination Intelligence'!CI5 | U11: ='Destination Intelligence'!CK5 | V11: ='Destination Intelligence'!CM5 | W11: ='Destination Intelligence'!CO5 | X11: ='Destination Intelligence'!CQ5 | Y11: ='Destination Intelligence'!CS5 | Z11: ='Destination Intelligence'!CU5 | AA11: ='Destination Intelligence'!CW5 | AB11: ='Destination Intelligence'!CY5 | AC11: ='Destination Intelligence'!DA5 | AD11: ='Destination Intelligence'!DC5 | AE11: ='Destination Intelligence'!DE5 | AF11: ='Destination Intelligence'!DG5 | AG11: ='Destination Intelligence'!DI5 | AH11: ='Destination Intelligence'!DK5 | AI11: ='Destination Intelligence'!DM5 | AJ11: ='Destination Intelligence'!DO5 | AK11: ='Destination Intelligence'!DQ5 | AL11: Wildlife, Island Hopping | AM11: Medium | AN11: india-amritsar-jallianwala-bagh
A12: ='Destination Intelligence'!B6 | B12: ='Destination Intelligence'!C6 | C12: ='Destination Intelligence'!D6 | D12: ='Destination Intelligence'!E6 | E12: ='Destination Intelligence'!G6 | F12: ='Destination Intelligence'!H6 | G12: ='Destination Intelligence'!BI6 | H12: ='Destination Intelligence'!BK6 | I12: ='Destination Intelligence'!BM6 | J12: ='Destination Intelligence'!BO6 | K12: ='Destination Intelligence'!BQ6 | L12: ='Destination Intelligence'!BS6 | M12: ='Destination Intelligence'!BU6 | N12: ='Destination Intelligence'!BW6 | O12: ='Destination Intelligence'!BY6 | P12: ='Destination Intelligence'!CA6 | Q12: ='Destination Intelligence'!CC6 | R12: ='Destination Intelligence'!CE6 | S12: ='Destination Intelligence'!CG6 | T12: ='Destination Intelligence'!CI6 | U12: ='Destination Intelligence'!CK6 | V12: ='Destination Intelligence'!CM6 | W12: ='Destination Intelligence'!CO6 | X12: ='Destination Intelligence'!CQ6 | Y12: ='Destination Intelligence'!CS6 | Z12: ='Destination Intelligence'!CU6 | AA12: ='Destination Intelligence'!CW6 | AB12: ='Destination Intelligence'!CY6 | AC12: ='Destination Intelligence'!DA6 | AD12: ='Destination Intelligence'!DC6 | AE12: ='Destination Intelligence'!DE6 | AF12: ='Destination Intelligence'!DG6 | AG12: ='Destination Intelligence'!DI6 | AH12: ='Destination Intelligence'!DK6 | AI12: ='Destination Intelligence'!DM6 | AJ12: ='Destination Intelligence'!DO6 | AK12: ='Destination Intelligence'!DQ6 | AL12: Wildlife, Shopping, Island Hopping | AM12: Medium | AN12: india-andaman-port-blair
A13: ='Destination Intelligence'!B7 | B13: ='Destination Intelligence'!C7 | C13: ='Destination Intelligence'!D7 | D13: ='Destination Intelligence'!E7 | E13: ='Destination Intelligence'!G7 | F13: ='Destination Intelligence'!H7 | G13: ='Destination Intelligence'!BI7 | H13: ='Destination Intelligence'!BK7 | I13: ='Destination Intelligence'!BM7 | J13: ='Destination Intelligence'!BO7 | K13: ='Destination Intelligence'!BQ7 | L13: ='Destination Intelligence'!BS7 | M13: ='Destination Intelligence'!BU7 | N13: ='Destination Intelligence'!BW7 | O13: ='Destination Intelligence'!BY7 | P13: ='Destination Intelligence'!CA7 | Q13: ='Destination Intelligence'!CC7 | R13: ='Destination Intelligence'!CE7 | S13: ='Destination Intelligence'!CG7 | T13: ='Destination Intelligence'!CI7 | U13: ='Destination Intelligence'!CK7 | V13: ='Destination Intelligence'!CM7 | W13: ='Destination Intelligence'!CO7 | X13: ='Destination Intelligence'!CQ7 | Y13: ='Destination Intelligence'!CS7 | Z13: ='Destination Intelligence'!CU7 | AA13: ='Destination Intelligence'!CW7 | AB13: ='Destination Intelligence'!CY7 | AC13: ='Destination Intelligence'!DA7 | AD13: ='Destination Intelligence'!DC7 | AE13: ='Destination Intelligence'!DE7 | AF13: ='Destination Intelligence'!DG7 | AG13: ='Destination Intelligence'!DI7 | AH13: ='Destination Intelligence'!DK7 | AI13: ='Destination Intelligence'!DM7 | AJ13: ='Destination Intelligence'!DO7 | AK13: ='Destination Intelligence'!DQ7 | AL13: Mountains, Wildlife, Shopping | AM13: Medium | AN13: india-andaman-havelock
A14: ='Destination Intelligence'!B8 | B14: ='Destination Intelligence'!C8 | C14: ='Destination Intelligence'!D8 | D14: ='Destination Intelligence'!E8 | E14: ='Destination Intelligence'!G8 | F14: ='Destination Intelligence'!H8 | G14: ='Destination Intelligence'!BI8 | H14: ='Destination Intelligence'!BK8 | I14: ='Destination Intelligence'!BM8 | J14: ='Destination Intelligence'!BO8 | K14: ='Destination Intelligence'!BQ8 | L14: ='Destination Intelligence'!BS8 | M14: ='Destination Intelligence'!BU8 | N14: ='Destination Intelligence'!BW8 | O14: ='Destination Intelligence'!BY8 | P14: ='Destination Intelligence'!CA8 | Q14: ='Destination Intelligence'!CC8 | R14: ='Destination Intelligence'!CE8 | S14: ='Destination Intelligence'!CG8 | T14: ='Destination Intelligence'!CI8 | U14: ='Destination Intelligence'!CK8 | V14: ='Destination Intelligence'!CM8 | W14: ='Destination Intelligence'!CO8 | X14: ='Destination Intelligence'!CQ8 | Y14: ='Destination Intelligence'!CS8 | Z14: ='Destination Intelligence'!CU8 | AA14: ='Destination Intelligence'!CW8 | AB14: ='Destination Intelligence'!CY8 | AC14: ='Destination Intelligence'!DA8 | AD14: ='Destination Intelligence'!DC8 | AE14: ='Destination Intelligence'!DE8 | AF14: ='Destination Intelligence'!DG8 | AG14: ='Destination Intelligence'!DI8 | AH14: ='Destination Intelligence'!DK8 | AI14: ='Destination Intelligence'!DM8 | AJ14: ='Destination Intelligence'!DO8 | AK14: ='Destination Intelligence'!DQ8 | AL14: Mountains, Wildlife, Shopping | AM14: Medium | AN14: india-andaman-neil-island
A15: ='Destination Intelligence'!B9 | B15: ='Destination Intelligence'!C9 | C15: ='Destination Intelligence'!D9 | D15: ='Destination Intelligence'!E9 | E15: ='Destination Intelligence'!G9 | F15: ='Destination Intelligence'!H9 | G15: ='Destination Intelligence'!BI9 | H15: ='Destination Intelligence'!BK9 | I15: ='Destination Intelligence'!BM9 | J15: ='Destination Intelligence'!BO9 | K15: ='Destination Intelligence'!BQ9 | L15: ='Destination Intelligence'!BS9 | M15: ='Destination Intelligence'!BU9 | N15: ='Destination Intelligence'!BW9 | O15: ='Destination Intelligence'!BY9 | P15: ='Destination Intelligence'!CA9 | Q15: ='Destination Intelligence'!CC9 | R15: ='Destination Intelligence'!CE9 | S15: ='Destination Intelligence'!CG9 | T15: ='Destination Intelligence'!CI9 | U15: ='Destination Intelligence'!CK9 | V15: ='Destination Intelligence'!CM9 | W15: ='Destination Intelligence'!CO9 | X15: ='Destination Intelligence'!CQ9 | Y15: ='Destination Intelligence'!CS9 | Z15: ='Destination Intelligence'!CU9 | AA15: ='Destination Intelligence'!CW9 | AB15: ='Destination Intelligence'!CY9 | AC15: ='Destination Intelligence'!DA9 | AD15: ='Destination Intelligence'!DC9 | AE15: ='Destination Intelligence'!DE9 | AF15: ='Destination Intelligence'!DG9 | AG15: ='Destination Intelligence'!DI9 | AH15: ='Destination Intelligence'!DK9 | AI15: ='Destination Intelligence'!DM9 | AJ15: ='Destination Intelligence'!DO9 | AK15: ='Destination Intelligence'!DQ9 | AL15: Wellness, Shopping | AM15: Medium | AN15: india-andaman-baratang-island
A16: ='Destination Intelligence'!B10 | B16: ='Destination Intelligence'!C10 | C16: ='Destination Intelligence'!D10 | D16: ='Destination Intelligence'!E10 | E16: ='Destination Intelligence'!G10 | F16: ='Destination Intelligence'!H10 | G16: ='Destination Intelligence'!BI10 | H16: ='Destination Intelligence'!BK10 | I16: ='Destination Intelligence'!BM10 | J16: ='Destination Intelligence'!BO10 | K16: ='Destination Intelligence'!BQ10 | L16: ='Destination Intelligence'!BS10 | M16: ='Destination Intelligence'!BU10 | N16: ='Destination Intelligence'!BW10 | O16: ='Destination Intelligence'!BY10 | P16: ='Destination Intelligence'!CA10 | Q16: ='Destination Intelligence'!CC10 | R16: ='Destination Intelligence'!CE10 | S16: ='Destination Intelligence'!CG10 | T16: ='Destination Intelligence'!CI10 | U16: ='Destination Intelligence'!CK10 | V16: ='Destination Intelligence'!CM10 | W16: ='Destination Intelligence'!CO10 | X16: ='Destination Intelligence'!CQ10 | Y16: ='Destination Intelligence'!CS10 | Z16: ='Destination Intelligence'!CU10 | AA16: ='Destination Intelligence'!CW10 | AB16: ='Destination Intelligence'!CY10 | AC16: ='Destination Intelligence'!DA10 | AD16: ='Destination Intelligence'!DC10 | AE16: ='Destination Intelligence'!DE10 | AF16: ='Destination Intelligence'!DG10 | AG16: ='Destination Intelligence'!DI10 | AH16: ='Destination Intelligence'!DK10 | AI16: ='Destination Intelligence'!DM10 | AJ16: ='Destination Intelligence'!DO10 | AK16: ='Destination Intelligence'!DQ10 | AL16: Wildlife, Shopping | AM16: Medium | AN16: india-andaman-ross-island
A17: ='Destination Intelligence'!B11 | B17: ='Destination Intelligence'!C11 | C17: ='Destination Intelligence'!D11 | D17: ='Destination Intelligence'!E11 | E17: ='Destination Intelligence'!G11 | F17: ='Destination Intelligence'!H11 | G17: ='Destination Intelligence'!BI11 | H17: ='Destination Intelligence'!BK11 | I17: ='Destination Intelligence'!BM11 | J17: ='Destination Intelligence'!BO11 | K17: ='Destination Intelligence'!BQ11 | L17: ='Destination Intelligence'!BS11 | M17: ='Destination Intelligence'!BU11 | N17: ='Destination Intelligence'!BW11 | O17: ='Destination Intelligence'!BY11 | P17: ='Destination Intelligence'!CA11 | Q17: ='Destination Intelligence'!CC11 | R17: ='Destination Intelligence'!CE11 | S17: ='Destination Intelligence'!CG11 | T17: ='Destination Intelligence'!CI11 | U17: ='Destination Intelligence'!CK11 | V17: ='Destination Intelligence'!CM11 | W17: ='Destination Intelligence'!CO11 | X17: ='Destination Intelligence'!CQ11 | Y17: ='Destination Intelligence'!CS11 | Z17: ='Destination Intelligence'!CU11 | AA17: ='Destination Intelligence'!CW11 | AB17: ='Destination Intelligence'!CY11 | AC17: ='Destination Intelligence'!DA11 | AD17: ='Destination Intelligence'!DC11 | AE17: ='Destination Intelligence'!DE11 | AF17: ='Destination Intelligence'!DG11 | AG17: ='Destination Intelligence'!DI11 | AH17: ='Destination Intelligence'!DK11 | AI17: ='Destination Intelligence'!DM11 | AJ17: ='Destination Intelligence'!DO11 | AK17: ='Destination Intelligence'!DQ11 | AL17: Mountains, Wildlife, Wellness | AM17: Medium | AN17: india-andaman-north-bay-island
A18: ='Destination Intelligence'!B12 | B18: ='Destination Intelligence'!C12 | C18: ='Destination Intelligence'!D12 | D18: ='Destination Intelligence'!E12 | E18: ='Destination Intelligence'!G12 | F18: ='Destination Intelligence'!H12 | G18: ='Destination Intelligence'!BI12 | H18: ='Destination Intelligence'!BK12 | I18: ='Destination Intelligence'!BM12 | J18: ='Destination Intelligence'!BO12 | K18: ='Destination Intelligence'!BQ12 | L18: ='Destination Intelligence'!BS12 | M18: ='Destination Intelligence'!BU12 | N18: ='Destination Intelligence'!BW12 | O18: ='Destination Intelligence'!BY12 | P18: ='Destination Intelligence'!CA12 | Q18: ='Destination Intelligence'!CC12 | R18: ='Destination Intelligence'!CE12 | S18: ='Destination Intelligence'!CG12 | T18: ='Destination Intelligence'!CI12 | U18: ='Destination Intelligence'!CK12 | V18: ='Destination Intelligence'!CM12 | W18: ='Destination Intelligence'!CO12 | X18: ='Destination Intelligence'!CQ12 | Y18: ='Destination Intelligence'!CS12 | Z18: ='Destination Intelligence'!CU12 | AA18: ='Destination Intelligence'!CW12 | AB18: ='Destination Intelligence'!CY12 | AC18: ='Destination Intelligence'!DA12 | AD18: ='Destination Intelligence'!DC12 | AE18: ='Destination Intelligence'!DE12 | AF18: ='Destination Intelligence'!DG12 | AG18: ='Destination Intelligence'!DI12 | AH18: ='Destination Intelligence'!DK12 | AI18: ='Destination Intelligence'!DM12 | AJ18: ='Destination Intelligence'!DO12 | AK18: ='Destination Intelligence'!DQ12 | AL18: Mountains, Wildlife | AM18: Medium | AN18: india-goa-north-goa
A19: ='Destination Intelligence'!B13 | B19: ='Destination Intelligence'!C13 | C19: ='Destination Intelligence'!D13 | D19: ='Destination Intelligence'!E13 | E19: ='Destination Intelligence'!G13 | F19: ='Destination Intelligence'!H13 | G19: ='Destination Intelligence'!BI13 | H19: ='Destination Intelligence'!BK13 | I19: ='Destination Intelligence'!BM13 | J19: ='Destination Intelligence'!BO13 | K19: ='Destination Intelligence'!BQ13 | L19: ='Destination Intelligence'!BS13 | M19: ='Destination Intelligence'!BU13 | N19: ='Destination Intelligence'!BW13 | O19: ='Destination Intelligence'!BY13 | P19: ='Destination Intelligence'!CA13 | Q19: ='Destination Intelligence'!CC13 | R19: ='Destination Intelligence'!CE13 | S19: ='Destination Intelligence'!CG13 | T19: ='Destination Intelligence'!CI13 | U19: ='Destination Intelligence'!CK13 | V19: ='Destination Intelligence'!CM13 | W19: ='Destination Intelligence'!CO13 | X19: ='Destination Intelligence'!CQ13 | Y19: ='Destination Intelligence'!CS13 | Z19: ='Destination Intelligence'!CU13 | AA19: ='Destination Intelligence'!CW13 | AB19: ='Destination Intelligence'!CY13 | AC19: ='Destination Intelligence'!DA13 | AD19: ='Destination Intelligence'!DC13 | AE19: ='Destination Intelligence'!DE13 | AF19: ='Destination Intelligence'!DG13 | AG19: ='Destination Intelligence'!DI13 | AH19: ='Destination Intelligence'!DK13 | AI19: ='Destination Intelligence'!DM13 | AJ19: ='Destination Intelligence'!DO13 | AK19: ='Destination Intelligence'!DQ13 | AL19: Mountains, Wildlife, Celebrations | AM19: Medium | AN19: india-goa-south-goa
... A114: ='Destination Intelligence'!B108 | B114: ='Destination Intelligence'!C108 | C114: ='Destination Intelligence'!D108 | D114: ='Destination Intelligence'!E108 | E114: ='Destination Intelligence'!G108 | F114: ='Destination Intelligence'!H108 | G114: ='Destination Intelligence'!BI108 | H114: ='Destination Intelligence'!BK108 | I114: ='Destination Intelligence'!BM108 | J114: ='Destination Intelligence'!BO108 | K114: ='Destination Intelligence'!BQ108 | L114: ='Destination Intelligence'!BS108 | M114: ='Destination Intelligence'!BU108 | N114: ='Destination Intelligence'!BW108 | O114: ='Destination Intelligence'!BY108 | P114: ='Destination Intelligence'!CA108 | Q114: ='Destination Intelligence'!CC108 | R114: ='Destination Intelligence'!CE108 | S114: ='Destination Intelligence'!CG108 | T114: ='Destination Intelligence'!CI108 | U114: ='Destination Intelligence'!CK108 | V114: ='Destination Intelligence'!CM108 | W114: ='Destination Intelligence'!CO108 | X114: ='Destination Intelligence'!CQ108 | Y114: ='Destination Intelligence'!CS108 | Z114: ='Destination Intelligence'!CU108 | AA114: ='Destination Intelligence'!CW108 | AB114: ='Destination Intelligence'!CY108 | AC114: ='Destination Intelligence'!DA108 | AD114: ='Destination Intelligence'!DC108 | AE114: ='Destination Intelligence'!DE108 | AF114: ='Destination Intelligence'!DG108 | AG114: ='Destination Intelligence'!DI108 | AH114: ='Destination Intelligence'!DK108 | AI114: ='Destination Intelligence'!DM108 | AJ114: ='Destination Intelligence'!DO108 | AK114: ='Destination Intelligence'!DQ108 | AL114: Mountains, Wildlife, Shopping | AM114: Medium | AN114: vietnam-da-nang

Sheet Destination Intelligence
A1: Source Row | B1: Destination ID | C1: Region ID | D1: Destination | E1: Region | F1: Travel Scope | G1: Record Type | H1: Journey Base Status | I1: Parent Region | J1: Journey Identity | K1: Primary Experiences | L1: Secondary Experiences | M1: Signature Experiences | N1: Best For | O1: Emotional Outcomes | P1: Strengths | Q1: Avoid When | R1: Comfort Range | S1: Journey Pace | T1: Suggested Minimum Duration | U1: Suggested Ideal Duration | V1: Best Season | W1: Shoulder Season | X1: Seasonal Cautions | Y1: Operational Confidence | Z1: Confidence Explanation | AA1: Airport or Arrival Gateway | AB1: Typical Transfer Complexity | AC1: Family Friendliness | AD1: Senior Friendliness | AE1: Accessibility Considerations | AF1: Business Travel Suitability | AG1: Connectivity Reliability | AH1: Food Variety | AI1: Vegetarian Friendliness | AJ1: Shopping Strength | AK1: Nightlife Strength | AL1: Wellness Strength | AM1: Adventure Intensity | AN1: Physical Activity Level | AO1: Arrival | AP1: First Impression | AQ1: Shared Moment | AR1: Signature Experience Seed | AS1: Relaxation Moment | AT1: Local Discovery | AU1: Food or Cultural Moment | AV1: Journey High Point | AW1: Journey Ending | AX1: Why This Region | AY1: Worth Considering | AZ1: Potential Trade-off | BA1: Suggested Duration | BB1: Journey Rhythm | BC1: Arrival Phase | BD1: Discovery Phase | BE1: Signature Day | BF1: Slow or Recovery Phase | BG1: Optional Extension | BH1: Departure Phase | BI1: Traveller — Solo Score | BJ1: Traveller — Solo Reason | BK1: Traveller — Couple Score | BL1: Traveller — Couple Reason | BM1: Traveller — Family Score | BN1: Traveller — Family Reason | BO1: Traveller — Friends Score | BP1: Traveller — Friends Reason | BQ1: Traveller — Business Score | BR1: Traveller — Business Reason | BS1: Emotion — Healing Score | BT1: Emotion — Healing Reason | BU1: Emotion — Celebration Score | BV1: Emotion — Celebration Reason | BW1: Emotion — Freedom Score | BX1: Emotion — Freedom Reason | BY1: Emotion — Escape Score | BZ1: Emotion — Escape Reason | CA1: Emotion — Adventure Score | CB1: Emotion — Adventure Reason | CC1: Emotion — Discovery Score | CD1: Emotion — Discovery Reason | CE1: Emotion — Reconnection Score | CF1: Emotion — Reconnection Reason | CG1: Emotion — Slow Living Score | CH1: Emotion — Slow Living Reason | CI1: Emotion — Relax Score | CJ1: Emotion — Relax Reason | CK1: Emotion — Explore Score | CL1: Emotion — Explore Reason | CM1: Emotion — Romance Score | CN1: Emotion — Romance Reason | CO1: Experience — Beach Score | CP1: Experience — Beach Reason | CQ1: Experience — Mountains Score | CR1: Experience — Mountains Reason | CS1: Experience — Wildlife Score | CT1: Experience — Wildlife Reason | CU1: Experience — Culture Score | CV1: Experience — Culture Reason | CW1: Experience — Food Score | CX1: Experience — Food Reason | CY1: Experience — Wellness Score | CZ1: Experience — Wellness Reason | DA1: Experience — Luxury Score | DB1: Experience — Luxury Reason | DC1: Experience — Shopping Score | DD1: Experience — Shopping Reason | DE1: Experience — Spiritual Score | DF1: Experience — Spiritual Reason | DG1: Experience — Adventure Score | DH1: Experience — Adventure Reason | DI1: Experience — Photography Score | DJ1: Experience — Photography Reason | DK1: Experience — Island Hopping Score | DL1: Experience — Island Hopping Reason | DM1: Experience — Heritage Score | DN1: Experience — Heritage Reason | DO1: Experience — Nature Score | DP1: Experience — Nature Reason | DQ1: Experience — Celebrations Score | DR1: Experience — Celebrations Reason
A2: 2 | B2: india-agra | C2: india-agra-agra | D2: Agra | E2: Agra | F2: Domestic | G2: City | H2: Yes | J2: Monumental Mughal heritage shaped by architecture, history, craft and romance. Agra is differentiated by heritage, culture, photography. | K2: Heritage, Culture, Photography | L2: Food | M2: Agra: Heritage, Culture, Photography with Food | N2: Solo, Family, Business | O2: Discovery, Explore, Reconnection, Freedom, Celebration | P2: Heritage, Culture, Photography; balanced / explorer rhythm; city context. | Q2: Avoid when the traveller requires Wildlife, Island Hopping as the journey's defining purpose. | R2: Balanced / Premium | S2: Balanced / Explorer | T2: 2 nights | U2: 2–3 nights | V2: Cooler months generally support more comfortable exploration. | W2: Spring and autumn require current heat and crowd review. | X2: Heat, haze, crowds and monument operating conditions require live confirmation. | Y2: Medium | Z2: Medium — suitable for business review; live service, access and season checks remain mandatory. | AA2: Agra rail/road gateway; Delhi connectivity commonly considered | AB2: Low / Moderate | AC2: High / Moderate | AD2: Moderate — supplier-specific review required | AE2: REVIEW_REQUIRED — confirm terrain, step-free access and supplier-specific support. | AF2: Strong | AG2: Generally Strong; live check required | AH2: Strong | AI2: Generally available; supplier confirmation required | AJ2: Limited | AK2: Limited | AL2: Limited / Supporting | AM2: Low / Moderate | AN2: Low / Moderate | AO2: Arrival through Agra rail/road gateway; Delhi connectivity commonly considered; protect time for transfer and orientation before Agra exploration. | AP2: Agra first impression centred on heritage, not broad Agra branding. | AQ2: Shared culture moment in Agra, paced for the selected traveller type. | AR2: Agra: Heritage, Culture, Photography with Food | AS2: A protected low-intensity pause after the principal heritage experience. | AT2: Region-specific discovery in Agra through food; verify local operator context. | AU2: A verified food moment rooted in Agra; confirm operating context. | AV2: Journey high point built around agra: heritage, culture, photography with food. | AW2: Unhurried departure from Agra with transfer conditions reconfirmed. | AX2: Agra is preferred when heritage, culture, photography are stronger than the destination's other regional personalities. | AY2: Heritage, Culture, Photography; balanced / explorer rhythm; city context. Suitable only after operational and seasonal checks. | AZ2: Heat, haze, crowds and monument operating conditions require live confirmation. | BA2: 2–3 nights | BB2: Balanced / Explorer | BC2: Arrival, transfer and orientation | BD2: Context-led food discovery | BE2: Agra: Heritage, Culture, Photography with Food | BF2: Protected slow time | BG2: REVIEW_REQUIRED — approve a compatible extension outside Agra. | BH2: Flexible departure with transfer buffer | BI2: 4 | BJ2: TRAVELLER_STRONG_MATCH — Heritage and Culture align with the solo characteristics in the workbook. | BK2: 3 | BL2: TRAVELLER_SUITABLE — Suitable with itinerary design tailored to couple priorities. | BM2: 4 | BN2: TRAVELLER_STRONG_MATCH — Heritage and Culture align with the family characteristics in the workbook. | BO2: 3 | BP2: TRAVELLER_SUITABLE — Suitable with itinerary design tailored to friends priorities. | BQ2: 4 | BR2: TRAVELLER_STRONG_MATCH — Heritage and Culture align with the business characteristics in the workbook. | BS2: 1 | BT2: EMOTION_WEAK_MATCH — Healing is not a defining outcome for this region record. | BU2: 3 | BV2: EMOTION_SUPPORTING_MATCH — Celebration can be supported as a secondary outcome with appropriate pacing. | BW2: 3 | BX2: EMOTION_SUPPORTING_MATCH — Freedom can be supported as a secondary outcome with appropriate pacing. | BY2: 1 | BZ2: EMOTION_WEAK_MATCH — Escape is not a defining outcome for this region record. | CA2: 1 | CB2: EMOTION_WEAK_MATCH — Adventure is not a defining outcome for this region record. | CC2: 5 | CD2: EMOTION_DIRECT_MATCH — Region-specific experiences directly support discovery. | CE2: 4 | CF2: EMOTION_DIRECT_MATCH — Region-specific experiences directly support reconnection. | CG2: 1 | CH2: EMOTION_WEAK_MATCH — Slow Living is not a defining outcome for this region record. | CI2: 1 | CJ2: EMOTION_WEAK_MATCH — Relax is not a defining outcome for this region record. | CK2: 4 | CL2: EMOTION_DIRECT_MATCH — Region-specific experiences directly support explore. | CM2: 1 | CN2: EMOTION_WEAK_MATCH — Romance is not a defining outcome for this region record. | CO2: 1 | CP2: EXPERIENCE_WEAK_MATCH — Beach is not a defining experience for this region. | CQ2: 1 | CR2: EXPERIENCE_WEAK_MATCH — Mountains is not a defining experience for this region. | CS2: 0 | CT2: CONTRADICTION_EXPERIENCE_MISMATCH — Do not select this record for a wildlife-first journey. | CU2: 5 | CV2: EXPERIENCE_PRIMARY_MATCH — Culture is a defining region-specific experience. | CW2: 4 | CX2: EXPERIENCE_SECONDARY_MATCH — Food is credible supporting intelligence for this region. | CY2: 1 | CZ2: EXPERIENCE_WEAK_MATCH — Wellness is not a defining experience for this region. | DA2: 1 | DB2: EXPERIENCE_WEAK_MATCH — Luxury is not a defining experience for this region. | DC2: 1 | DD2: EXPERIENCE_WEAK_MATCH — Shopping is not a defining experience for this region. | DE2: 1 | DF2: EXPERIENCE_WEAK_MATCH — Spiritual is not a defining experience for this region. | DG2: 1 | DH2: EXPERIENCE_WEAK_MATCH — Adventure is not a defining experience for this region. | DI2: 5 | DJ2: EXPERIENCE_PRIMARY_MATCH — Photography is a defining region-specific experience. | DK2: 0 | DL2: CONTRADICTION_EXPERIENCE_MISMATCH — Do not select this record for a island hopping-first journey. | DM2: 5 | DN2: EXPERIENCE_PRIMARY_MATCH — Heritage is a defining region-specific experience. | DO2: 1 | DP2: EXPERIENCE_WEAK_MATCH — Nature is not a defining experience for this region. | DQ2: 1 | DR2: EXPERIENCE_WEAK_MATCH — Celebrations is not a defining experience for this region.
A3: 3 | B3: india-amritsar | C3: india-amritsar-golden-temple | D3: Amritsar | E3: Golden Temple | F3: Domestic | G3: Attraction | H3: No | I3: Amritsar | J3: Golden Temple is an attraction within Amritsar, not an independent destination personality. | K3: Spiritual, Heritage, Culture | L3: Photography | M3: Context-led visit to Golden Temple | N3: REVIEW_REQUIRED | O3: Healing, Reconnection, Slow Living, Discovery, Explore, Freedom | P3: Spiritual, Heritage, Culture; relaxed / balanced rhythm; attraction context. | Q3: Avoid when the traveller requires Celebrations, Wildlife, Island Hopping as the journey's defining purpose. | R3: Simple / Balanced / Premium | S3: Relaxed / Balanced | T3: Half day | U3: Half to full day | V3: Cooler months are generally more comfortable. | W3: Transitional months can work with heat planning. | X3: Sacred protocols, event crowds and heat require current review. | Y3: Medium | Z3: Medium — identity is supported, but this record must not be treated as an independent journey base. | AA3: Amritsar airport / rail gateway | AB3: Moderate | AC3: High / Moderate | AD3: Moderate — supplier-specific review required | AE3: REVIEW_REQUIRED — confirm terrain, step-free access and supplier-specific support. | AF3: Limited | AG3: Moderate; live check required | AH3: Moderate / REVIEW_REQUIRED | AI3: Generally available; supplier confirmation required | AJ3: Limited | AK3: Limited | AL3: Limited / Supporting | AM3: Low / Moderate | AN3: Low / Moderate | AO3: Arrival through Amritsar airport / rail gateway; protect time for transfer and orientation before Golden Temple exploration. | AP3: Golden Temple first impression centred on spiritual, not broad Amritsar branding. | AQ3: Shared heritage moment in Golden Temple, paced for the selected traveller type. | AR3: Context-led visit to Golden Temple | AS3: A protected low-intensity pause after the principal spiritual experience. | AT3: Region-specific discovery in Golden Temple through photography; verify local operator context. | AU3: A verified cultural moment rooted in Golden Temple; confirm operating context. | AV3: Journey high point built around context-led visit to golden temple. | AW3: Unhurried departure from Golden Temple with transfer conditions reconfirmed. | AX3: Golden Temple is preferred when spiritual, heritage, culture are stronger than the destination's other regional personalities. | AY3: Spiritual, Heritage, Culture; relaxed / balanced rhythm; attraction context. Suitable only after operational and seasonal checks. | AZ3: Sacred protocols, event crowds and heat require current review. | BA3: Half to full day | BB3: Relaxed / Balanced | BC3: Arrival, transfer and orientation | BD3: Context-led photography discovery | BE3: Context-led visit to Golden Temple | BF3: Protected slow time | BG3: REVIEW_REQUIRED — approve a compatible extension outside Golden Temple. | BH3: Flexible departure with transfer buffer | BI3: 3 | BJ3: TRAVELLER_SUITABLE — Suitable with itinerary design tailored to solo priorities. | BK3: 3 | BL3: TRAVELLER_SUITABLE — Suitable with itinerary design tailored to couple priorities. | BM3: 3 | BN3: TRAVELLER_SUITABLE — Suitable with itinerary design tailored to family priorities. | BO3: 3 | BP3: TRAVELLER_SUITABLE — Suitable with itinerary design tailored to friends priorities. | BQ3: 2 | BR3: TRAVELLER_LIMITED — This record is not a natural standalone business base; use only with a clear purpose. | BS3: 5 | BT3: EMOTION_DIRECT_MATCH — Region-specific experiences directly support healing. | BU3: 1 | BV3: EMOTION_WEAK_MATCH — Celebration is not a defining outcome for this region record. | BW3: 3 | BX3: EMOTION_SUPPORTING_MATCH — Freedom can be supported as a secondary outcome with appropriate pacing. | BY3: 1 | BZ3: EMOTION_WEAK_MATCH — Escape is not a defining outcome for this region record. | CA3: 1 | CB3: EMOTION_WEAK_MATCH — Adventure is not a defining outcome for this region record. | CC3: 3 | CD3: EMOTION_SUPPORTING_MATCH — Discovery can be supported as a secondary outcome with appropriate pacing. | CE3: 4 | CF3: EMOTION_DIRECT_MATCH — Region-specific experiences directly support reconnection. | CG3: 4 | CH3: EMOTION_DIRECT_MATCH — Region-specific experiences directly support slow living. | CI3: 1 | CJ3: EMOTION_WEAK_MATCH — Relax is not a defining outcome for this region record. | CK3: 3 | CL3: EMOTION_SUPPORTING_MATCH — Explore can be supported as a secondary outcome with appropriate pacing. | CM3: 1 | CN3: EMOTION_WEAK_MATCH — Romance is not a defining outcome for this region record. | CO3: 1 | CP3: EXPERIENCE_WEAK_MATCH — Beach is not a defining experience for this region. | CQ3: 1 | CR3: EXPERIENCE_WEAK_MATCH — Mountains is not a defining experience for this region. | CS3: 0 | CT3: CONTRADICTION_EXPERIENCE_MISMATCH — Do not select this record for a wildlife-first journey. | CU3: 5 | CV3: EXPERIENCE_PRIMARY_MATCH — Culture is a defining region-specific experience. | CW3: 1 | CX3: EXPERIENCE_WEAK_MATCH — Food is not a defining experience for this region. | CY3: 1 | CZ3: EXPERIENCE_WEAK_MATCH — Wellness is not a defining experience for this region. | DA3: 1 | DB3: EXPERIENCE_WEAK_MATCH — Luxury is not a defining experience for this region. | DC3: 1 | DD3: EXPERIENCE_WEAK_MATCH — Shopping is not a defining experience for this region. | DE3: 5 | DF3: EXPERIENCE_PRIMARY_MATCH — Spiritual is a defining region-specific experience. | DG3: 1 | DH3: EXPERIENCE_WEAK_MATCH — Adventure is not a defining experience for this region. | DI3: 4 | DJ3: EXPERIENCE_SECONDARY_MATCH — Photography is credible supporting intelligence for this region. | DK3: 0 | DL3: CONTRADICTION_EXPERIENCE_MISMATCH — Do not select this record for a island hopping-first journey. | DM3: 5 | DN3: EXPERIENCE_PRIMARY_MATCH — Heritage is a defining region-specific experience. | DO3: 1 | DP3: EXPERIENCE_WEAK_MATCH — Nature is not a defining experience for this region. | DQ3: 0 | DR3: CONTRADICTION_EXPERIENCE_MISMATCH — Do not select this record for a celebrations-first journey.
A4: 4 | B4: india-amritsar | C4: india-amritsar-wagah-border | D4: Amritsar | E4: Wagah Border | F4: Domestic | G4: Attraction | H4: No | I4: Amritsar | J4: Wagah Border is an attraction within Amritsar, not an independent destination personality. | K4: Celebrations, Culture, Photography | M4: Context-led visit to Wagah Border | N4: REVIEW_REQUIRED | O4: Celebration, Reconnection, Romance, Discovery, Explore, Freedom | P4: Celebrations, Culture, Photography; relaxed / balanced rhythm; attraction context. | Q4: Avoid when the traveller requires Wildlife, Spiritual as the journey's defining purpose. | R4: Simple / Balanced / Premium | S4: Relaxed / Balanced | T4: Half day | U4: Half to full day | V4: Cooler months are generally more comfortable. | W4: Transitional months can work with heat planning. | X4: Sacred protocols, event crowds and heat require current review. | Y4: Medium | Z4: Medium — identity is supported, but this record must not be treated as an independent journey base. | AA4: Amritsar airport / rail gateway | AB4: Moderate | AC4: High / Moderate | AD4: Moderate — supplier-specific review required | AE4: REVIEW_REQUIRED — confirm terrain, step-free access and supplier-specific support. | AF4: Limited | AG4: Moderate; live check required | AH4: Moderate / REVIEW_REQUIRED | AI4: Generally available; supplier confirmation required | AJ4: Limited | AK4: Strong / Region-specific | AL4: Limited / Supporting | AM4: Low / Moderate | AN4: Low / Moderate | AO4: Arrival through Amritsar airport / rail gateway; protect time for transfer and orientation before Wagah Border exploration. | AP4: Wagah Border first impression centred on celebrations, not broad Amritsar branding. | AQ4: Shared culture moment in Wagah Border, paced for the selected traveller type. | AR4: Context-led visit to Wagah Border | AS4: A protected low-intensity pause after the principal celebrations experience. | AT4: Region-specific discovery in Wagah Border through celebrations; verify local operator context. | AU4: A verified cultural moment rooted in Wagah Border; confirm operating context. | AV4: Journey high point built around context-led visit to wagah border. | AW4: Unhurried departure from Wagah Border with transfer conditions reconfirmed. | AX4: Wagah Border is preferred when celebrations, culture, photography are stronger than the destination's other regional personalities. | AY4: Celebrations, Culture, Photography; relaxed / balanced rhythm; attraction context. Suitable only after operational and seasonal checks. | AZ4: Sacred protocols, event crowds and heat require current review. | BA4: Half to full day | BB4: Relaxed / Balanced | BC4: Arrival, transfer and orientation | BD4: Context-led celebrations discovery | BE4: Context-led visit to Wagah Border | BF4: Protected slow time | BG4: REVIEW_REQUIRED — approve a compatible extension outside Wagah Border. | BH4: Flexible departure with transfer buffer | BI4: 3 | BJ4: TRAVELLER_SUITABLE — Suitable with itinerary design tailored to solo priorities. | BK4: 3 | BL4: TRAVELLER_SUITABLE — Suitable with itinerary design tailored to couple priorities. | BM4: 3 | BN4: TRAVELLER_SUITABLE — Suitable with itinerary design tailored to family priorities. | BO4: 3 | BP4: TRAVELLER_SUITABLE — Suitable with itinerary design tailored to friends priorities. | BQ4: 2 | BR4: TRAVELLER_LIMITED — This record is not a natural standalone business base; use only with a clear purpose. | BS4: 1 | BT4: EMOTION_WEAK_MATCH — Healing is not a defining outcome for this region record. | BU4: 5 | BV4: EMOTION_DIRECT_MATCH — Region-specific experiences directly support celebration. | BW4: 3 | BX4: EMOTION_SUPPORTING_MATCH — Freedom can be supported as a secondary outcome with appropriate pacing. | BY4: 1 | BZ4: EMOTION_WEAK_MATCH — Escape is not a defining outcome for this region record. | CA4: 1 | CB4: EMOTION_WEAK_MATCH — Adventure is not a defining outcome for this region record. | CC4: 3 | CD4: EMOTION_SUPPORTING_MATCH — Discovery can be supported as a secondary outcome with appropriate pacing. | CE4: 4 | CF4: EMOTION_DIRECT_MATCH — Region-specific experiences directly support reconnection. | CG4: 1 | CH4: EMOTION_WEAK_MATCH — Slow Living is not a defining outcome for this region record. | CI4: 1 | CJ4: EMOTION_WEAK_MATCH — Relax is not a defining outcome for this region record. | CK4: 3 | CL4: EMOTION_SUPPORTING_MATCH — Explore can be supported as a secondary outcome with appropriate pacing. | CM4: 4 | CN4: EMOTION_DIRECT_MATCH — Region-specific experiences directly support romance. | CO4: 1 | CP4: EXPERIENCE_WEAK_MATCH — Beach is not a defining experience for this region. | CQ4: 1 | CR4: EXPERIENCE_WEAK_MATCH — Mountains is not a defining experience for this region. | CS4: 0 | CT4: CONTRADICTION_EXPERIENCE_MISMATCH — Do not select this record for a wildlife-first journey. | CU4: 5 | CV4: EXPERIENCE_PRIMARY_MATCH — Culture is a defining region-specific experience. | CW4: 1 | CX4: EXPERIENCE_WEAK_MATCH — Food is not a defining experience for this region. | CY4: 1 | CZ4: EXPERIENCE_WEAK_MATCH — Wellness is not a defining experience for this region. | DA4: 1 | DB4: EXPERIENCE_WEAK_MATCH — Luxury is not a defining experience for this region. | DC4: 1 | DD4: EXPERIENCE_WEAK_MATCH — Shopping is not a defining experience for this region. | DE4: 0 | DF4: CONTRADICTION_EXPERIENCE_MISMATCH — Do not select this record for a spiritual-first journey. | DG4: 1 | DH4: EXPERIENCE_WEAK_MATCH — Adventure is not a defining experience for this region. | DI4: 5 | DJ4: EXPERIENCE_PRIMARY_MATCH — Photography is a defining region-specific experience. | DK4: 1 | DL4: EXPERIENCE_WEAK_MATCH — Island Hopping is not a defining experience for this region. | DM4: 1 | DN4: EXPERIENCE_WEAK_MATCH — Heritage is not a defining experience for this region. | DO4: 1 | DP4: EXPERIENCE_WEAK_MATCH — Nature is not a defining experience for this region. | DQ4: 5 | DR4: EXPERIENCE_PRIMARY_MATCH — Celebrations is a defining region-specific experience.
A5: 5 | B5: india-amritsar | C5: india-amritsar-jallianwala-bagh | D5: Amritsar | E5: Jallianwala Bagh | F5: Domestic | G5: Attraction | H5: No | I5: Amritsar | J5: Jallianwala Bagh is an attraction within Amritsar, not an independent destination personality. | K5: Heritage, Culture, Photography | M5: Context-led visit to Jallianwala Bagh | N5: REVIEW_REQUIRED | O5: Discovery, Explore, Reconnection, Freedom | P5: Heritage, Culture, Photography; relaxed / balanced rhythm; attraction context. | Q5: Avoid when the traveller requires Wildlife, Island Hopping as the journey's defining purpose. | R5: Simple / Balanced / Premium | S5: Relaxed / Balanced | T5: Half day | U5: Half to full day | V5: Cooler months are generally more comfortable. | W5: Transitional months can work with heat planning. | X5: Sacred protocols, event crowds and heat require current review. | Y5: Medium | Z5: Medium — identity is supported, but this record must not be treated as an independent journey base. | AA5: Amritsar airport / rail gateway | AB5: Moderate | AC5: High / Moderate | AD5: Moderate — supplier-specific review required | AE5: REVIEW_REQUIRED — confirm terrain, step-free access and supplier-specific support. | AF5: Limited | AG5: Moderate; live check required | AH5: Moderate / REVIEW_REQUIRED | AI5: Generally available; supplier confirmation required | AJ5: Limited | AK5: Limited | AL5: Limited / Supporting | AM5: Low / Moderate | AN5: Low / Moderate | AO5: Arrival through Amritsar airport / rail gateway; protect time for transfer and orientation before Jallianwala Bagh exploration. | AP5: Jallianwala Bagh first impression centred on heritage, not broad Amritsar branding. | AQ5: Shared culture moment in Jallianwala Bagh, paced for the selected traveller type. | AR5: Context-led visit to Jallianwala Bagh | AS5: A protected low-intensity pause after the principal heritage experience. | AT5: Region-specific discovery in Jallianwala Bagh through heritage; verify local operator context. | AU5: A verified cultural moment rooted in Jallianwala Bagh; confirm operating context. | AV5: Journey high point built around context-led visit to jallianwala bagh. | AW5: Unhurried departure from Jallianwala Bagh with transfer conditions reconfirmed. | AX5: Jallianwala Bagh is preferred when heritage, culture, photography are stronger than the destination's other regional personalities. | AY5: Heritage, Culture, Photography; relaxed / balanced rhythm; attraction context. Suitable only after operational and seasonal checks. | AZ5: Sacred protocols, event crowds and heat require current review. | BA5: Half to full day | BB5: Relaxed / Balanced | BC5: Arrival, transfer and orientation | BD5: Context-led heritage discovery | BE5: Context-led visit to Jallianwala Bagh | BF5: Protected slow time | BG5: REVIEW_REQUIRED — approve a compatible extension outside Jallianwala Bagh. | BH5: Flexible departure with transfer buffer | BI5: 3 | BJ5: TRAVELLER_SUITABLE — Suitable with itinerary design tailored to solo priorities. | BK5: 3 | BL5: TRAVELLER_SUITABLE — Suitable with itinerary design tailored to couple priorities. | BM5: 3 | BN5: TRAVELLER_SUITABLE — Suitable with itinerary design tailored to family priorities. | BO5: 3 | BP5: TRAVELLER_SUITABLE — Suitable with itinerary design tailored to friends priorities. | BQ5: 2 | BR5: TRAVELLER_LIMITED — This record is not a natural standalone business base; use only with a clear purpose. | BS5: 1 | BT5: EMOTION_WEAK_MATCH — Healing is not a defining outcome for this region record. | BU5: 1 | BV5: EMOTION_WEAK_MATCH — Celebration is not a defining outcome for this region record. | BW5: 3 | BX5: EMOTION_SUPPORTING_MATCH — Freedom can be supported as a secondary outcome with appropriate pacing. | BY5: 1 | BZ5: EMOTION_WEAK_MATCH — Escape is not a defining outcome for this region record. | CA5: 1 | CB5: EMOTION_WEAK_MATCH — Adventure is not a defining outcome for this region record. | CC5: 5 | CD5: EMOTION_DIRECT_MATCH — Region-specific experiences directly support discovery. | CE5: 4 | CF5: EMOTION_DIRECT_MATCH — Region-specific experiences directly support reconnection. | CG5: 1 | CH5: EMOTION_WEAK_MATCH — Slow Living is not a defining outcome for this region record. | CI5: 1 | CJ5: EMOTION_WEAK_MATCH — Relax is not a defining outcome for this region record. | CK5: 4 | CL5: EMOTION_DIRECT_MATCH — Region-specific experiences directly support explore. | CM5: 1 | CN5: EMOTION_WEAK_MATCH — Romance is not a defining outcome for this region record. | CO5: 1 | CP5: EXPERIENCE_WEAK_MATCH — Beach is not a defining experience for this region. | CQ5: 1 | CR5: EXPERIENCE_WEAK_MATCH — Mountains is not a defining experience for this region. | CS5: 0 | CT5: CONTRADICTION_EXPERIENCE_MISMATCH — Do not select this record for a wildlife-first journey. | CU5: 5 | CV5: EXPERIENCE_PRIMARY_MATCH — Culture is a defining region-specific experience. | CW5: 1 | CX5: EXPERIENCE_WEAK_MATCH — Food is not a defining experience for this region. | CY5: 1 | CZ5: EXPERIENCE_WEAK_MATCH — Wellness is not a defining experience for this region. | DA5: 1 | DB5: EXPERIENCE_WEAK_MATCH — Luxury is not a defining experience for this region. | DC5: 1 | DD5: EXPERIENCE_WEAK_MATCH — Shopping is not a defining experience for this region. | DE5: 1 | DF5: EXPERIENCE_WEAK_MATCH — Spiritual is not a defining experience for this region. | DG5: 1 | DH5: EXPERIENCE_WEAK_MATCH — Adventure is not a defining experience for this region. | DI5: 5 | DJ5: EXPERIENCE_PRIMARY_MATCH — Photography is a defining region-specific experience. | DK5: 0 | DL5: CONTRADICTION_EXPERIENCE_MISMATCH — Do not select this record for a island hopping-first journey. | DM5: 5 | DN5: EXPERIENCE_PRIMARY_MATCH — Heritage is a defining region-specific experience. | DO5: 1 | DP5: EXPERIENCE_WEAK_MATCH — Nature is not a defining experience for this region. | DQ5: 1 | DR5: EXPERIENCE_WEAK_MATCH — Celebrations is not a defining experience for this region.
A6: 6 | B6: india-andaman | C6: india-andaman-port-blair | D6: Andaman | E6: Port Blair | F6: Domestic | G6: Journey Base | H6: Yes | I6: Andaman | J6: An island journey combining beaches, marine nature, history and inter-island discovery. Port Blair is differentiated by heritage, culture, nature. | K6: Heritage, Culture, Nature | L6: Food | M6: Port Blair: Heritage, Culture, Nature with Food | N6: Solo, Family | O6: Discovery, Explore, Reconnection, Healing, Relax, Celebration | P6: Heritage, Culture, Nature; relaxed / balanced rhythm; journey base context. | Q6: Avoid when the traveller requires Wildlife, Island Hopping, Shopping as the journey's defining purpose. | R6: Balanced / Premium | S6: Relaxed / Balanced | T6: 2 nights | U6: 3 nights | V6: Sea and weather conditions determine practical suitability. | W6: Shoulder periods require ferry and marine-condition checks. | X6: Ferries, weather and water activities require live operational confirmation. | Y6: Medium | Z6: Medium — suitable for business review; live service, access and season checks remain mandatory. | AA6: Port Blair | AB6: Moderate | AC6: High / Moderate | AD6: Moderate — supplier-specific review required | AE6: REVIEW_REQUIRED — confirm terrain, step-free access and supplier-specific support. | AF6: Limited | AG6: Moderate; live check required | AH6: Strong | AI6: Generally available; supplier confirmation required | AJ6: Limited | AK6: Limited | AL6: Limited / Supporting | AM6: Low / Moderate | AN6: Low / Moderate | AO6: Arrival through Port Blair; protect time for transfer and orientation before Port Blair exploration. | AP6: Port Blair first impression centred on heritage, not broad Andaman branding. | AQ6: Shared culture moment in Port Blair, paced for the selected traveller type. | AR6: Port Blair: Heritage, Culture, Nature with Food | AS6: Unscheduled pause connected to Port Blair's heritage setting. | AT6: Region-specific discovery in Port Blair through food; verify local operator context. | AU6: A verified food moment rooted in Port Blair; confirm operating context. | AV6: Journey high point built around port blair: heritage, culture, nature with food. | AW6: Unhurried departure from Port Blair with transfer conditions reconfirmed. | AX6: Port Blair is preferred when heritage, culture, nature are stronger than the destination's other regional personalities. | AY6: Heritage, Culture, Nature; relaxed / balanced rhythm; journey base context. Suitable only after operational and seasonal checks. | AZ6: Ferries, weather and water activities require live operational confirmation. | BA6: 3 nights | BB6: Relaxed / Balanced | BC6: Arrival, transfer and orientation | BD6: Context-led food discovery | BE6: Port Blair: Heritage, Culture, Nature with Food | BF6: Protected slow time | BG6: REVIEW_REQUIRED — approve a compatible extension outside Port Blair. | BH6: Flexible departure with transfer buffer | BI6: 4 | BJ6: TRAVELLER_STRONG_MATCH — Heritage and Culture align with the solo characteristics in the workbook. | BK6: 3 | BL6: TRAVELLER_SUITABLE — Suitable with itinerary design tailored to couple priorities. | BM6: 4 | BN6: TRAVELLER_STRONG_MATCH — Heritage and Culture align with the family characteristics in the workbook. | BO6: 3 | BP6: TRAVELLER_SUITABLE — Suitable with itinerary design tailored to friends priorities. | BQ6: 2 | BR6: TRAVELLER_LIMITED — This record is not a natural standalone business base; use only with a clear purpose. | BS6: 3 | BT6: EMOTION_SUPPORTING_MATCH — Healing can be supported as a secondary outcome with appropriate pacing. | BU6: 3 | BV6: EMOTION_SUPPORTING_MATCH — Celebration can be supported as a secondary outcome with appropriate pacing. | BW6: 1 | BX6: EMOTION_WEAK_MATCH — Freedom is not a defining outcome for this region record. | BY6: 1 | BZ6: EMOTION_WEAK_MATCH — Escape is not a defining outcome for this region record. | CA6: 1 | CB6: EMOTION_WEAK_MATCH — Adventure is not a defining outcome for this region record. | CC6: 5 | CD6: EMOTION_DIRECT_MATCH — Region-specific experiences directly support discovery. | CE6: 4 | CF6: EMOTION_DIRECT_MATCH — Region-specific experiences directly support reconnection. | CG6: 1 | CH6: EMOTION_WEAK_MATCH — Slow Living is not a defining outcome for this region record. | CI6: 3 | CJ6: EMOTION_SUPPORTING_MATCH — Relax can be supported as a secondary outcome with appropriate pacing. | CK6: 4 | CL6: EMOTION_DIRECT_MATCH — Region-specific experiences directly support explore. | CM6: 1 | CN6: EMOTION_WEAK_MATCH — Romance is not a defining outcome for this region record. | CO6: 1 | CP6: EXPERIENCE_WEAK_MATCH — Beach is not a defining experience for this region. | CQ6: 1 | CR6: EXPERIENCE_WEAK_MATCH — Mountains is not a defining experience for this region. | CS6: 0 | CT6: CONTRADICTION_EXPERIENCE_MISMATCH — Do not select this record for a wildlife-first journey. | CU6: 5 | CV6: EXPERIENCE_PRIMARY_MATCH — Culture is a defining region-specific experience. | CW6: 4 | CX6: EXPERIENCE_SECONDARY_MATCH — Food is credible supporting intelligence for this region. | CY6: 1 | CZ6: EXPERIENCE_WEAK_MATCH — Wellness is not a defining experience for this region. | DA6: 1 | DB6: EXPERIENCE_WEAK_MATCH — Luxury is not a defining experience for this region. | DC6: 0 | DD6: CONTRADICTION_EXPERIENCE_MISMATCH — Do not select this record for a shopping-first journey. | DE6: 1 | DF6: EXPERIENCE_WEAK_MATCH — Spiritual is not a defining experience for this region. | DG6: 1 | DH6: EXPERIENCE_WEAK_MATCH — Adventure is not a defining experience for this region. | DI6: 1 | DJ6: EXPERIENCE_WEAK_MATCH — Photography is not a defining experience for this region. | DK6: 0 | DL6: CONTRADICTION_EXPERIENCE_MISMATCH — Do not select this record for a island hopping-first journey. | DM6: 5 | DN6: EXPERIENCE_PRIMARY_MATCH — Heritage is a defining region-specific experience. | DO6: 5 | DP6: EXPERIENCE_PRIMARY_MATCH — Nature is a defining region-specific experience. | DQ6: 1 | DR6: EXPERIENCE_WEAK_MATCH — Celebrations is not a defining experience for this region.
